<?xml version="1.0"?>
<robot name="softlegisaac">
<link name="world"/>
<joint name="fixed" type="fixed">
  <origin xyz="0. 0. 0." rpy="0. 0. 0."/>
  <parent link="world"/>
  <child link="cart_link"/>
</joint>
  <joint name="cart_joint" type="prismatic">
    <origin xyz="0. -0.005 0.0 " rpy="3.1415927 -1.5707963 0. "/>
    <parent link="cart_link"/>
    <child link="base_link"/>
    <axis xyz="1 0 0"/>
    <joint_properties damping=".0" friction="0.4"/>
    <limit lower="0.0" upper="10.0" effort="500." velocity="1000."/>
  </joint>
  <joint name="hip_joint" type="revolute">
    <origin xyz="0. -0.255 0.07 " rpy="0. -1.5707963 0. "/>
    <parent link="base_link"/>
    <child link="thigh_link"/>
    <axis xyz="1 0 0"/>
    <limit lower="-3.1415927" upper="3.1415927" effort="100." velocity="57.6059555"/>
  </joint>
  <joint name="knee_joint" type="revolute">
    <origin xyz="0.0275 -0.175 0. " rpy="1.5707964 0. 0. "/>
    <parent link="thigh_link"/>
    <child link="calf_link"/>
    <axis xyz="1 0 0"/>
    <limit lower="-3.1415927" upper="3.1415927" effort="100." velocity="57.6059555"/>
  </joint>
  <link name="base_link">
    <inertial>
      <origin xyz="0. 0. 0." rpy="0. 0. 0."/>
      <mass value="0.9724552"/>
      <inertia ixx="0.0016984399" ixy="-0.00098390475" ixz="-0.0013053791" iyy="0.020148637999999996" iyz="0.00015383174" izz="0.019764512999999997"/>
    </inertial>
    <visual>
      <origin xyz="0. 0. 0." rpy="0. 0. -1.5707964"/>
      <geometry>
      <mesh filename="package://softleg_description/meshes/base.stl" scale="0.001 0.001 0.001"/>
      </geometry>
    </visual>
    <collision>
    <origin xyz="-0.0004043 -0.256 0.04 " rpy="0. 0. -1.5707964"/>
      <geometry>
        <cylinder radius="0.035" length="0.025"/>
      </geometry>
    </collision>
  </link>
  <link name="calf_link">
    <inertial>
      <origin xyz="0. 0. 0." rpy="0. 0. 0."/>
      <mass value="0.0762175"/>
      <inertia ixx="6.0006428999999995e-05" ixy="-0.011984835" ixz="3.6890095e-10" iyy="0.00047243319" iyz="1.2686112999999998e-10" izz="0.0005204986699999999"/>
    </inertial>
    <visual>
      <origin xyz="-0. 0. -0." rpy="0. -1.5707963 0. "/>
      <geometry>
        <mesh filename="package://softleg_description/meshes/calf.stl" scale="0.001 0.001 0.001"/>
      </geometry>
    </visual>
     <collision>
    <origin xyz="0.018 0. 0.175" rpy="0. -1.5707963 0. "/>
      <geometry>
        <sphere radius="0.015"/>
      </geometry>
    </collision>
  </link>
  <link name="cart_link">
    <inertial>
      <origin xyz="0. 0.0 0." rpy="0. 0. 0."/>
      <mass value="1e-4"/>
      <inertia ixx="1e-5" ixy="1e-5" ixz="1e-5" iyy="1e-5" iyz="1e-5" izz="1e-5"/>
    </inertial>
    <visual>
      <origin xyz="0. 0. 0." rpy="0. 0. -3.1415925"/>
      <geometry>
        <mesh filename="package://softleg_description/meshes/cart.stl" scale="0.001 0.001 0.001"/>
      </geometry>
    </visual>
  </link>
  <link name="thigh_link">
    <inertial>
      <origin xyz="0. 0. 0." rpy="0. 0. 0."/>
      <mass value="0.435789"/>
      <inertia ixx="1e-5" ixy="1e-5" ixz="1e-5" iyy="1e-5" iyz="1e-5" izz="1e-5"/>
    </inertial>
    <visual>
      <origin xyz="0. -0.073 0. " rpy="0. 0. -1.5707964"/>
      <geometry>
        <mesh filename="package://softleg_description/meshes/thigh.stl" scale="0.001 0.001 0.001"/>
      </geometry>
    </visual>
    <collision>
    <origin xyz="0.0125 -0.1840615 0. " rpy="1.5707964 0. -1.5707964"/>
      <geometry>
        <cylinder radius="0.03" length="0.027"/>
      </geometry>
    </collision>
  </link>

  <ros2_control name="GazeboSystem" type="system">
    <hardware>
      <plugin>gazebo_ros2_control/GazeboSystem</plugin>
    </hardware>
    <joint name="cart_joint">
      <!-- <command_interface name="effort" /> -->
      <state_interface name="position">
          <param name="initial_value">-0.0</param>
      </state_interface>
      <state_interface name="velocity">
          <param name="initial_value">0.0</param>
      </state_interface>
      <state_interface name="effort" />
    </joint>     
    <joint name="hip_joint">
      <command_interface name="effort" />
      <state_interface name="position">
          <param name="initial_value">-0.0</param>
      </state_interface>
      <state_interface name="velocity">
          <param name="initial_value">0.0</param>
      </state_interface>
      <state_interface name="effort" />
    </joint>
    <joint name="knee_joint">
        <command_interface name="effort" />
        <state_interface name="position">
            <param name="initial_value">-0.0</param>
        </state_interface>
        <state_interface name="velocity">
            <param name="initial_value">0.0</param>
        </state_interface>
        <state_interface name="effort" />
    </joint>
  </ros2_control>
  
  <gazebo>
    <!-- <plugin filename="libgazebo_ros2_control.so" name="gazebo_ros2_control">
      <parameters>/home/yurs/softleg_ws/src/softleg_gazebo/config/softleg_gazebo_sim_jnt_PD.yaml</parameters>
    </plugin> -->
    <plugin filename="libgazebo_ros2_control.so" name="gazebo_ros2_control">
      <!-- <robot_param>robot_description</robot_param>
      <robot_param_node>robot_state_publisher</robot_param_node> -->
      <parameters>/home/yurs/softleg_ws/src/softleg_gazebo/config/softleg_gazebo_sim_jnt_PD.yaml</parameters>
      <!-- <controller_manager_name>simulation_controller_manager</controller_manager_name> -->
    </plugin>
  </gazebo>
  
  <gazebo reference="cart_link">
    <gravity>true</gravity>
    <material>Gazebo/White</material>
    <kp>100000.0</kp>
    <kd>1000.0</kd>
    <mu1>0.0</mu1>
    <mu2>0.0</mu2>
    <slip1>0.1</slip1>
    <slip2>0.1</slip2>
    <collision>
      <surface>
        <contact>
          <ode>
          <min_depth>0.0</min_depth>
          </ode>
        </contact>
      </surface>
    </collision>
  </gazebo>
  
  <gazebo reference="base_link">
    <gravity>true</gravity>
    <material>Gazebo/White</material>
    <!-- <kp>1e15</kp>
    <kd>1e15</kd>
    <mu>5.0</mu>
    <mu2>0.0</mu2>
    <slip1>0.0</slip1>
    <slip2>0.0</slip2>
    <collision>
      <surface>
        <contact>
          <ode>
            <min_depth>0.0</min_depth>
          </ode>
        </contact>
      </surface>
    </collision> -->
  </gazebo>
  <gazebo reference="thigh_link">
    <gravity>true</gravity>
    <material>Gazebo/White</material>
    <!-- <kp>1e6</kp>
    <kd>1e2</kd>
    <mu1>1</mu1>
    <mu2>1</mu2>
    <slip1>0</slip1>
    <slip2>0</slip2>
    <collision>
      <surface>
        <contact>
          <ode>
            <min_depth>0.01</min_depth>
          </ode>
        </contact>
      </surface>
    </collision> -->
  </gazebo>
  <gazebo reference="calf_link">
    <gravity>true</gravity>
    <material>Gazebo/White</material>
    <collision>
    <surface>
      <friction>
        <ode>
          <!-- <mu>5.0</mu> -->
          <!-- <mu1>1.5</mu1> 
          <mu2>1.5</mu2>  -->
          <!-- <fdir1>0 0 1</fdir1> -->
          <!-- <slip1>0.0</slip1> -->
          <!-- <slip2>0.0</slip2> -->
        </ode>
      </friction>
      <contact>
        <ode>
          <!-- <kp>1000000.0</kp>
          <kd>1000.0</kd> -->
          <!-- <maxVel>1000.0</maxVel> -->
          <!-- <maxContacts>1</maxContacts>
          <min_depth>0.00</min_depth> -->
        </ode>
      </contact>
    </surface>
  </collision>
  </gazebo> 
</robot>
